Workbook

Sheet BO
A1: Estado do Rio Grande do Sul
A2: MUNICÍPIO DE INDEPENDÊNCIA
A3: DEMONSTRAÇÕES CONTÁBEIS CONSOLIDADAS
F4: CNPJ | G4: 12.091.144/0001-80
A5: BALANÇO ORÇAMENTÁRIO
F6: Exercício: | G6: 2015
A8: Quadro Principal
A9: RECEITAS ORÇAMENTÁRIAS | B9: Previsão Inicial (a) | C9: Previsão Atualizada (b) | D9: Receitas Realizadas ( c) | E9: SALDO (d) = (c-b)
A10: Receitas Correntes (I) | B10: =SUM(B11:B18) -> 0 | C10: =SUM(C11:C18) -> 0 | D10: =SUM(D11:D18) -> 0 | E10: =D10-C10 -> 0
A11: Receita Tributária | E11: =D11-C11 -> 0
A12: Receita de Contribuições | E12: =D12-C12 -> 0
A13: Receita Patrimonial | E13: =D13-C13 -> 0
A14: Receita Agropecuária | E14: =D14-C14 -> 0
A15: Receita Industrial | E15: =D15-C15 -> 0
A16: Receita de Serviços | E16: =D16-C16 -> 0
A17: Transferências Correntes | E17: =D17-C17 -> 0
A18: Outras Receitas Correntes | E18: =D18-C18 -> 0
A19: Receitas de Capital (II) | B19: =SUM(B20:B24) -> 0 | C19: =SUM(C20:C24) -> 0 | D19: =SUM(D20:D24) -> 0 | E19: =D19-C19 -> 0
A20: Operações de Crédito | E20: =D20-C20 -> 0
A21: Alienação de Bens | E21: =D21-C21 -> 0
A22: Amortizações de Empréstimos | E22: =D22-C22 -> 0
A23: Transferências de Capital | E23: =D23-C23 -> 0
A24: Outras Receitas de Capital | E24: =D24-C24 -> 0
A25: Recursos Arrecadados em Exercícios Anteriores (III) | E25: =D25-C25 -> 0
A26: SUBTOTAL DAS RECEITAS (IV) = (I + II + III) | B26: =B10+B19+B25 -> 0 | C26: =C10+C19+C25 -> 0 | D26: =D10+D19+D25 -> 0 | E26: =D26-C26 -> 0
A27: Operações de Crédito/ Refinanciamento (V) | B27: =B28+B31 -> 0 | C27: =C28+C31 -> 0 | D27: =D28+D31 -> 0 | E27: =D27-C27 -> 0
A28: Operações de Crédito Internas | B28: =SUM(B29:B30) -> 0 | C28: =SUM(C29:C30) -> 0 | D28: =SUM(D29:D30) -> 0 | E28: =D28-C28 -> 0
A29: Mobiliária | E29: =D29-C29 -> 0
A30: Contratual | E30: =D30-C30 -> 0
A31: Operações de Crédito Externas | B31: =SUM(B32:B33) -> 0 | E31: =D31-C31 -> 0
A32: Mobiliária | E32: =D32-C32 -> 0
A33: Contratual | E33: =D33-C33 -> 0
A34: SUBTOTAL COM REFINANCIAMENTO (VI) = (IV + V) | B34: =B26+B27 -> 0 | C34: =C26+C27 -> 0 | D34: =D26+D27 -> 0 | E34: =D34-C34 -> 0
A35: Déficit (VII) | B35: =IF(B34<B60,B60-B34,0) -> 0 | C35: =IF(C34<C60,C60-C34,0) -> 0 | D35: =IF(D34<D60,D60-D34,0) -> 0 | E35: =D35-C35 -> 0
A36: TOTAL (VIII) = (VI + VII) | B36: =B34+B35 -> 0 | C36: =C34+C35 -> 0 | D36: =D34+D35 -> 0 | E36: =D36-C36 -> 0
A37: Saldos de Exercícios Anteriores (Utilizados Para Créditos Adicionais) | B37: =SUM(B38:B39) -> 0 | C37: =SUM(C38:C39) -> 0 | D37: =SUM(D38:D39) -> 0 | E37: =D37-C37 -> 0
A38: Superávit Financeiro | E38: =D38-C38 -> 0
A39: Reabertura de Créditos Adicionais | E39: =D39-C39 -> 0
A41: DESPESAS ORÇAMENTÁRIAS | B41: Dotação Inicial (e) | C41: Dotação Atualizada (f) | D41: Despesas Empenhadas (g) | E41: Despesas Liquidadas (h) | F41: Despesas Pagas (i) | G41: Saldo da Dotação (j) = (f-g)
A42: Despesas Correntes (IX) | B42: =SUM(B43:B45) -> 0 | C42: =SUM(C43:C45) -> 0 | D42: =SUM(D43:D45) -> 0 | E42: =SUM(E43:E45) -> 0 | F42: =SUM(F43:F45) -> 0 | G42: =C42-D42 -> 0
...

Sheet BF
A1: =BO!A1 -> Estado do Rio Grande do Sul
A2: =BO!A2 -> MUNICÍPIO DE INDEPENDÊNCIA
A3: =BO!A3 -> DEMONSTRAÇÕES CONTÁBEIS CONSOLIDADAS
F4: CNPJ | G4: =BO!G4 -> 12.091.144/0001-80
A5: BALANÇO FINANCEIRO
F6: Exercício: | G6: =BO!G6 -> 2015
A8: Quadro Principal
A9: INGRESSOS | E9: DISPÊNDIOS
A10: ESPECIFICAÇÃO | B10: Exercício Atual | C10: Exercício Anterior | E10: ESPECIFICAÇÃO | F10: Exercício Atual | G10: Exercício Anterior
A11: Receita Orçamentária (I) | B11: =B12+B13 -> 0 | C11: =C12+C13 -> 0 | E11: Despesa Orçamentária (VI) | F11: =F12+F13 -> 0 | G11: =G12+G13 -> 0
A12: Ordinária | E12: Ordinária
A13: Vinculada | B13: =SUM(B14:B19) -> 0 | C13: =SUM(C14:C19) -> 0 | E13: Vinculada | F13: =SUM(F14:F19) -> 0 | G13: =SUM(G14:G19) -> 0
A14: Recursos Vinculados à Educação | E14: Recursos Destinados à Educação
A15: Recursos Vinculados à Saúde | E15: Recursos Destinados à Saúde
A16: Recursos Vinculados à Previdência Social - RPPS | E16: Recursos Destinado a Previdência Social - RPPS
A17: Recursos Vinculados à Previdência Social - RGPS | E17: Recursos Destinado a Previdência Social - RGPS
A18: Recursos Vinculados à Seguridade Social | E18: Recursos Destinado a Seguridade Social
A19: Outras Destinações de Recursos | E19: Outras Destinações de Recursos
A20: Transferências Financeiras Recebidas (II) | B20: =SUM(B21:B24) -> 0 | C20: =SUM(C21:C24) -> 0 | E20: Transferências Financeiras Concedidas (VII) | F20: =SUM(F21:F24) -> 0 | G20: =SUM(G21:G24) -> 0
A21: Transferências Recebidas para a Execução Orçamentária | E21: Transferências Concedidas para a Execução Orçamentária
A22: Transferências Recebidas Independentes de Execução Orçamentária | E22: Transferências Concedidas Independentes de Execução Orçamentária
A23: Transferências Recebidas para Aportes de recursos para o RPPS | E23: Transferências Concedidas para Aportes de recursos para o RPPS
A24: Transferências Recebidas para Aportes de recursos para o RGPS | E24: Transferências Concedidas para Aportes de recursos para o RGPS
A25: Recebimentos Extraorçamentários (III) | B25: =SUM(B26:B29) -> 0 | C25: =SUM(C26:C29) -> 0 | E25: Pagamentos Extraorçamentários (VIII) | F25: =SUM(F26:F29) -> 0 | G25: =SUM(G26:G29) -> 0
A26: Inscrição de Restos a Pagar Não Processados | E26: Pagamentos de Restos a Pagar Não Processados
A27: Inscrição de Restos a Pagar Processados | E27: Pagamentos de Restos a Pagar Processados
A28: Depósitos Restituíveis e Valores Vinculados | E28: Depósitos Restituíveis e Valores Vinculados
A29: Outros Recebimentos Extraorçamentários | E29: Outros Pagamentos Extraorçamentários
A30: Saldo do Exercício Anterior (IV) | B30: =SUM(B31:B33) -> 0 | C30: =SUM(C31:C33) -> 0 | E30: Saldo para o Exercício Seguinte (IX) | F30: =SUM(F31:F33) -> 0 | G30: =SUM(G31:G33) -> 0
A31: Caixa e Equivalentes de Caixa | E31: Caixa e Equivalentes de Caixa
A32: Depósitos Restituíveis e Valores Vinculados | E32: Depósitos Restituíveis e Valores Vinculados
A33: Investimentos e Aplicações Temporárias a Curto Prazo | E33: Investimentos e Aplicações Temporárias a Curto Prazo
A34: TOTAL (V) = (I+II+III+IV) | B34: =B11+B20+B25+B30 -> 0 | C34: =C11+C20+C25+C30 -> 0 | E34: TOTAL (X) = (VI+VII+VIII+IX) | F34: =F11+F20+F25+F30 -> 0 | G34: =G11+G20+G25+G30 -> 0
A36: Quadro Anexo
A37: ESPECIFICAÇÃO | B37: Exercício Atual | E37: Exercício Anterior
B38: Receita Orçamentária | C38: Deduções da Receita Orçamentária | D38: Saldo | E38: Receita Orçamentária | F38: Deduções da Receita Orçamentária | G38: Saldo
B39: (a) | C39: (b) | D39: (c) = (a - b) | E39: (d) | F39: (e) | G39: (f) = (d - e)
A40: Ordinária | D40: =B40-C40 -> 0 | G40: =E40-F40 -> 0
A41: Vinculada | B41: =SUM(B42:B47) -> 0 | C41: =SUM(C42:C47) -> 0 | D41: =SUM(D42:D47) -> 0 | E41: =SUM(E42:E47) -> 0 | F41: =SUM(F42:F47) -> 0 | G41: =SUM(G42:G47) -> 0
A42: Recursos Vinculados à Educação | D42: =B42-C42 -> 0 | G42: =E42-F42 -> 0
...

Sheet BP
A1: =BO!A1 -> Estado do Rio Grande do Sul
A2: =BO!A2 -> MUNICÍPIO DE INDEPENDÊNCIA
A3: =BO!A3 -> DEMONSTRAÇÕES CONTÁBEIS CONSOLIDADAS
B4: CNPJ | C4: =BO!G4 -> 12.091.144/0001-80
A5: BALANÇO PATRIMONIAL
B6: Exercício: | C6: =BO!G6 -> 2015
A8: Quadro Principal
A9: Campo | B9: Exercício Atual | C9: Exercício Anterior
A10: ATIVO | B10: =B11+B17 -> 0 | C10: =C11+C17 -> 0
A11: Ativo Circulante | B11: =SUM(B12:B16) -> 0 | C11: =SUM(C12:C16) -> 0
A12: Caixa e Equivalentes de Caixa
A13: Créditos a Curto Prazo
A14: Investimentos e Aplicações Temporárias a Curto Prazo
A15: Estoques
A16: VPD Pagas Antecipadamente
A17: Ativo Não Circulante | B17: =B18+B23+B24+B25+B26 -> 0 | C17: =C18+C23+C24+C25+C26 -> 0
A18: Realizável a Longo Prazo | B18: =SUM(B19:B22) -> 0 | C18: =SUM(C19:C22) -> 0
A19: Créditos a Longo Prazo
A20: Investimentos Temporários a Longo Prazo
A21: Estoques
A22: VPD pagas antecipadamente
A23: Investimentos
A24: Imobilizado
A25: Intangível
A26: Diferido
A27: PASSIVO E PATRIMÔNIO LÍQUIDO | B27: =B28+B36+B44 -> 0 | C27: =C28+C36+C44 -> 0
A28: Passivo Circulante | B28: =SUM(B29:B35) -> 0 | C28: =SUM(C29:C35) -> 0
A29: Obrigações Trabalhistas, Previdenciárias e Assistenciais a Pagar a Curto Prazo
A30: Empréstimos e Financiamentos a Curto Prazo
A31: Fornecedores e Contas a Pagar a Curto Prazo
A32: Obrigações Fiscais a Curto Prazo
A33: Obrigações de Repartições a Outros Entes
A34: Provisões a Curto Prazo
A35: Demais Obrigações a Curto Prazo
A36: Passivo Não Circulante | B36: =SUM(B37:B43) -> 0 | C36: =SUM(C37:C43) -> 0
A37: Obrigações Trabalhistas, Previdenciárias e Assistenciais a Pagar a Longo Prazo
A38: Empréstimos e Financiamentos a Longo Prazo
A39: Fornecedores e Contas a Pagar a Longo Prazo
A40: Obrigações Fiscais a Longo Prazo
A41: Provisões a Longo Prazo
...

Sheet DVP
A1: =BO!A1 -> Estado do Rio Grande do Sul
A2: =BO!A2 -> MUNICÍPIO DE INDEPENDÊNCIA
A3: =BO!A3 -> DEMONSTRAÇÕES CONTÁBEIS CONSOLIDADAS
A4: CNPJ | B4: =BO!G4 -> 12.091.144/0001-80
A5: DEMONSTRAÇÃO DAS VARIAÇÕES PATRIMONIAIS
B6: Exercício: | C6: =BO!G6 -> 2015
A8: Conta | B8: Exercício Atual | C8: Exercício Anterior
A9: VARIAÇÕES PATRIMONIAIS AUMENTATIVAS | B9: =B10+B14+B19+B23+B30+B40+B46 -> 0 | C9: =C10+C14+C19+C23+C30+C40+C46 -> 0
A10: Impostos, Taxas e Contribuições de Melhoria | B10: =SUM(B11:B13) -> 0 | C10: =SUM(C11:C13) -> 0
A11: Impostos
A12: Taxas
A13: Contribuições de Melhoria
A14: Contribuições | B14: =SUM(B15:B18) -> 0 | C14: =SUM(C15:C18) -> 0
A15: Contribuições Sociais
A16: Contribuições de Intervenção no domínio econômico
A17: Contribuição de Iluminação Pública
A18: Contribuições de Interesse das Categorias Profissionais
A19: Exploração e Venda de Bens, Serviços e Direitos | B19: =SUM(B20:B22) -> 0 | C19: =SUM(C20:C22) -> 0
A20: Venda de Mercadorias
A21: Venda de Produtos
A22: Exploração de Bens e Direitos e Prestação de Serviços
A23: Variações Patrimoniais Aumentativas Financeiras | B23: =SUM(B24:B29) -> 0 | C23: =SUM(C24:C29) -> 0
A24: Juros e Encargos de Empréstimos e Financiamentos Concedidos
A25: Juros e Encargos de Mora
A26: Variações Monetárias e Cambiais
A27: Descontos Financeiros Obtidos
A28: Remuneração de Depósitos Bancários e Aplicações Financeiras
A29: Outras Variações Patrimoniais Aumentativas – Financeiras
A30: Transferências e Delegações Recebidas | B30: =SUM(B31:B39) -> 0 | C30: =SUM(C31:C39) -> 0
A31: Transferências Intragovernamentais
A32: Transferências Intergovernamentais
A33: Transferências das Instituições Privadas
A34: Transferências das Instituições Multigovernamentais
A35: Transferências de Consórcios Públicos
A36: Transferências do Exterior
A37: Execução Orçamentária Delegada de Entes
A38: Transferências de Pessoas Físicas
A39: Outras Transferências e Delegações Recebidas
A40: Valorização e Ganhos com Ativos e Desincorporação de Passivos | B40: =SUM(B41:B45) -> 0 | C40: =SUM(C41:C45) -> 0
A41: Reavaliação de Ativos
...

Sheet DFC
A1: =BO!A1 -> Estado do Rio Grande do Sul
A2: =BO!A2 -> MUNICÍPIO DE INDEPENDÊNCIA
A3: =BO!A3 -> DEMONSTRAÇÕES CONTÁBEIS CONSOLIDADAS
B4: CNPJ | C4: =BO!G4 -> 12.091.144/0001-80
A5: DEMONSTRAÇÃO DO FLUXO DE CAIXA
B6: Exercício: | C6: =BO!G6 -> 2015
A8: Campo | B8: Exercício Atual | C8: Exercício Anterior
A9: FLUXOS DE CAIXA DAS ATIVIDADES OPERACIONAIS (I) | B9: =B10-B29 -> 0 | C9: =C10-C29 -> 0
A10: Ingressos | B10: =B11+B20+B27 -> 0 | C10: =C11+C20+C27 -> 0
A11: Receitas derivadas e originárias | B11: =SUM(B12:B19) -> 0 | C11: =SUM(C12:C19) -> 0
A12: Receita Tributária
A13: Receita de Contribuições
A14: Receita Patrimonial
A15: Receita Agropecuária
A16: Receita Industrial
A17: Receita de Serviços
A18: Remuneração das Disponibilidades
A19: Outras Receitas Derivadas e Originárias
A20: Transferências correntes recebidas | B20: =B21+B25+B26 -> 0 | C20: =C21+C25+C26 -> 0
A21: Intergovernamentais | B21: =SUM(B22:B24) -> 0 | C21: =SUM(C22:C24) -> 0
A22: da União
A23: de Estados e Distrito Federal
A24: de Municípios
A25: Intragovernamentais
A26: Outras transferências correntes recebidas
A27: Outros ingressos operacionais
A28: Desembolsos | B28: =B29+B58+B62+B69 -> 0 | C28: =C29+C58+C62+C69 -> 0
A29: Pessoal e demais despesas | B29: =SUM(B30:B57) -> 0 | C29: =SUM(C30:C57) -> 0
A30: Legislativa
A31: Judiciária
A32: Essencial à Justiça
A33: Administração
A34: Defesa Nacional
A35: Segurança Pública
A36: Relações Exteriores
A37: Assistência Social
A38: Previdência Social
A39: Saúde
A40: Trabalho
A41: Educação
...

Sheet Consistência
A1: Teste | B1: Valor 1 | C1: Valor 2 | D1: Diferença
A2: Caixa inicial da DFC = Caixa final do ano anterior da DFC | B2: =DFC!B89 -> 0 | C2: =DFC!C90 -> 0 | D2: =B2-C2 -> 0
A3: Caixa inicial da DFC = Caixa inicial do BF | B3: =DFC!B89 -> 0 | C3: =BF!B30 -> 0 | D3: =B3-C3 -> 0
A4: Caixa final da DFC = Caixa final do BF | B4: =DFC!B90 -> 0 | C4: =BF!F30 -> 0 | D4: =B4-C4 -> 0
A5: Caixa final da DFC (informado) = Caixa final da DFC (calculado) | B5: =DFC!B90 -> 0 | C5: =DFC!B89+DFC!B10-DFC!B28+DFC!B71-DFC!B75+DFC!B80-DFC!B85 -> 0 | D5: =B5-C5 -> 0
A6: Caixa final da DFC = Caixa + Investimentos do BP | B6: =DFC!B90 -> 0 | C6: =BP!B12+BP!B14+BP!B20 -> 0 | D6: =B6-C6 -> 0
A7: Caixa inicial da DFC = Caixa + Investimentos do BP (ano anterior) | B7: =DFC!B89 -> 0 | C7: =BP!C12+BP!C14+BP!C20 -> 0 | D7: =B7-C7 -> 0
A8: VPA - VPD da DVP + Resultados Acumulados do ano anterior do BP = Resultados Acumulados do BP | B8: =DVP!B9-DVP!B52+BP!C51 -> 0 | C8: =BP!B51 -> 0 | D8: =B8-C8 -> 0
A9: Ativo Financeiro - Passivo Financeiro do BP = Superávit financeiro do BP | B9: =BP!B57-BP!B60 -> 0 | C9: =BP!B114 -> 0 | D9: =B9-C9 -> 0
A10: Ativo do BP = Passivo e PL do BP | B10: =BP!B10 -> 0 | C10: =BP!B27 -> 0 | D10: =B10-C10 -> 0
A11: Ativo do BP (ano anterior) = Passivo e PL do BP (ano anterior) | B11: =BP!C10 -> 0 | C11: =BP!C27 -> 0 | D11: =B11-C11 -> 0
A12: Ativo do BP = Ativo Financeiro + Ativo Permanente do BP | B12: =BP!B10 -> 0 | C12: =BP!B56 -> 0 | D12: =B12-C12 -> 0
A13: Passivo do BP = Passivo Financeiro + Passivo Permanente do BP | B13: =BP!B28+BP!B36 -> 0 | C13: =BP!B60+BP!B61 -> 0 | D13: =B13-C13 -> 0
A14: Receita Orçamentária do BF = Receita Orçamentária do BO | B14: =BF!B11 -> 0 | C14: =BO!D34 -> 0 | D14: =B14-C14 -> 0
A15: Despesa Empenhada do BF = Despesa Empenhada do BO | B15: =BF!F11 -> 0 | C15: =BO!D60 -> 0 | D15: =B15-C15 -> 0
A16: Pagamento de Restos a Pagar Não processados do BF = Restos a Pagar Não Processados pagos do BO | B16: =BF!F26 -> 0 | C16: =BO!E75 -> 0 | D16: =B16-C16 -> 0
A17: Pagamento de Restos a Pagar processados do BF = Restos a Pagar Processados pagos do BO | B17: =BF!F27 -> 0 | C17: =BO!D88 -> 0 | D17: =B17-C17 -> 0
A18: Caixa final da BF (informado) = Caixa final do BF (calculado) | B18: =BF!F30 -> 0 | C18: =BF!B30+BF!B11+BF!B20+BF!B25-BF!F11-BF!F20-BF!F25 -> 0 | D18: =B18-C18 -> 0
A19: Total de ingressos do BF = Total de dispêndios do BF | B19: =BF!B34 -> 0 | C19: =BF!F34 -> 0 | D19: =B19-C19 -> 0
