Workbook

Sheet Instruções
A1: Instruções de Uso
A2: Para acrescentar um mês, copiar toda a última coluna da direita e escluir os valores das células da nova coluna que não estão com fundo cinza claro.
A3: As células com fundo cinza claro possuem fórmulas. Altere-as se souber o que estiver fazendo.
A4: Preencha primeiro a guia TCERS pois a guia STN busca alguns valores de lá (que estão em células fundo cinza claro).

Sheet TCERS
A1: Índice de Despesa total com Pessoal (metodologia do TCE/RS - IN 18/2015)
A2: Item | C2: 42186 | D2: 42217 | E2: 42248 | F2: 42278 | G2: 42309 | H2: 42339 | I2: 42370 | J2: 42401 | K2: 42430 | L2: 42461 | M2: 42491 | N2: 42522 | O2: 42552 | P2: 42583
A3: DTP/RCL | N3: =IF(N44>0,N4/N5,"") -> 0.50221124 | O3: =IF(O4>0,O4/O5,"") -> 0.5074974 | P3: =IF(P4>0,P4/P5,"") -> 0.50255834
A4: Despesa Total com Pessoal (últimos 12 meses) | N4: =SUM(C7:N7) -> 8339497 | O4: =SUM(D7:O7) -> 8430836 | P4: =SUM(E7:P7) -> 8478319.1
A5: Receita Corrente Líquida (últimos 12 meses) | N5: =SUM(C44:N44) -> 16605556 | O5: =SUM(D44:O44) -> 16612570 | P5: =SUM(E44:P44) -> 16870318
A7: DTP | B7: (1 - 2 - 3 + 4) | C7: =C8-C9-C35+C40 -> 592956.43 | D7: =D8-D9-D35+D40 -> 601541.92 | E7: =E8-E9-E35+E40 -> 600558.82 | F7: =F8-F9-F35+F40 -> 631199.28 | G7: =G8-G9-G35+G40 -> 612875.7 | H7: =H8-H9-H35+H40 -> 1168894.2 | I7: =I8-I9-I35+I40 -> 698512.82 | J7: =J8-J9-J35+J40 -> 699325.71 | ... P7: =P8-P9-P35+P40 -> 649025.02
A8: 1 - PESSOAL E ENCARGOS SOCIAIS | B8: 3.1.0.0.00.00.00.00.00 | C8: 784063.29 | D8: 792722.81 | E8: 795163.29 | F8: 825028.42 | G8: 800853.78 | H8: 1541354.6 | I8: 950180.06 | J8: 944216.23 | K8: 883913.86 | L8: 918301.64 | M8: 898228.19 | N8: 957114.77 | O8: 939290.47 | P8: 895845.18
A9: 2 - NATUREZAS DE DESPESA | C9: =SUM(C10:C34) -> 173501.7 | D9: =SUM(D10:D34) -> 174886.68 | E9: =SUM(E10:E34) -> 177371.96 | F9: =SUM(F10:F34) -> 172545.62 | G9: =SUM(G10:G34) -> 169935.03 | H9: =SUM(H10:H34) -> 335738.36 | I9: =SUM(I10:I34) -> 219304.71 | J9: =SUM(J10:J34) -> 218547.06 | ... P9: =SUM(P10:P34) -> 224884.97
A10: Aposentadorias do RPPS, Reserva Remunerada e Reformas dos Militares (Fonte 0050 RPPS) | B10: 3.1.9.0.01.00.00.00.00 | C10: 57711.23 | D10: 57711.23 | E10: 57711.23 | F10: 57711.23 | G10: 57711.23 | H10: 116707.58 | I10: 77284.95 | J10: 81897.21 | K10: 79860.1 | L10: 79860.1 | M10: 79860.1 | N10: 79860.1 | O10: 80625.97 | P10: 78832.16
A11: Pensões do RPPS e do Militar | B11: 3.1.9.0.03.00.00.00.00 | C11: 23580.32 | D11: 23580.32 | E11: 23580.32 | F11: 23580.32 | G11: 23580.32 | H11: 47160.64 | I11: 26410.03 | J11: 30454.21 | K11: 30334.38 | L11: 30334.38 | M11: 30334.38 | N11: 30744.31 | O11: 37678.09 | P11: 40827.04
A12: Outros Benefícios Previdenciários – Pessoal Ativo (Fonte 0050 RPPS) | B12: 3.1.9.0.05.00.01.00.00 | C12: 37892.99 | D12: 38467.54 | E12: 41167.21 | F12: 35897.36 | G12: 32721.77 | H12: 61179.3 | I12: 38187.96 | J12: 38302.58 | K12: 29505 | L12: 25412.26 | M12: 29697.23 | N12: 32661 | O12: 42799.24 | P12: 39709.75
A13: Outros Benefícios Previdenciários – Pessoal Inativo (Fonte 0050 RPPS) | B13: 3.1.9.0.05.00.02.00.00
A14: Outros Benefícios Previdenciários – Pensionistas | B14: 3.1.9.0.05.00.03.00.00
A15: Outros Benefícios Assistenciais do Servidor e do Militar | B15: 3.1.9.0.08.00.00.00.00
A16: Abono de Permanência | B16: 3.1.9.0.11.07.00.00.00
A17: Licença Prêmio Indenizada | B17: 3.1.9.0.11.48.00.00.00
A18: Representação Mensal | B18: 3.1.9.0.11.75.00.00.00
A19: INSS Sobre Sessão Extraordinária - Agentes Políticos | B19: 3.1.9.0.13.02.04.00.00
A20: INSS Sobre Convocação Extraordinária - Agentes Políticos | B20: 3.1.9.0.13.02.05.00.00
A21: Convocação Extraordinária | B21: 3.1.9.0.16.04.00.00.00
A22: Ajuda de Custo | B22: 3.1.9.0.16.99.01.00.00
A23: Remoções | B23: 3.1.9.0.16.99.02.00.00
A24: Sessões Extraordinárias | B24: 3.1.9.0.16.99.03.00.00
... A33: Plano de Seguridade Social do Pensionista | B33: 3.1.9.1.13.12.00.00.00
A34: Amortização do Passivo Atuarial com RPPS - Alíquota Suplementar | B34: 3.1.9.1.13.99.01.00.00 | C34: 54317.16 | D34: 55127.59 | E34: 54913.2 | F34: 55356.71 | G34: 55921.71 | H34: 110690.84 | I34: 77421.77 | J34: 67893.06 | K34: 66424.54 | L34: 66845.63 | M34: 66838.83 | N34: 68518.53 | O34: 69398.32 | P34: 65516.02
A35: 3 - NATUREZAS DE RECEITA | C35: =SUM(C36:C39) -> 17605.16 | D35: =SUM(D36:D39) -> 16294.21 | E35: =SUM(E36:E39) -> 17232.51 | F35: =SUM(F36:F39) -> 21283.52 | G35: =SUM(G36:G39) -> 18043.05 | H35: =SUM(H36:H39) -> 36722 | I35: =SUM(I36:I39) -> 32362.53 | J35: =SUM(J36:J39) -> 26343.46 | ... P35: =SUM(P36:P39) -> 21935.19
A36: (-) IRRF Sobre o Rendimento do Trabalho – Ativos / Inativos do Poder Executivo / Indiretas | B36: (1.1.1.2.04.31.01.00.00) | C36: 17605.16 | D36: 16294.21 | E36: 17232.51 | F36: 21283.52 | G36: 18043.05 | H36: 36722 | I36: 32362.53 | J36: 26343.46 | K36: 22415.76 | L36: 22288.74 | M36: 21984.55 | N36: 30146.45 | O36: 24493.39 | P36: 21935.19
A37: (-) Multas e Juros de Mora do IRRF | B37: (1.9.1.1.02.03.00.00.00)
A38: (-) Multas e Juros de Mora da Dívida Ativa do IRRF | B38: (1.9.1.3.02.03.00.00.00)
A39: (-) Receita da Dívida Ativa do IRRF | B39: (1.9.3.1.01.03.00.00.00)
A40: 4 - CONTAS PATRIMONIAIS | C40: =SUM(C41:C42) -> 0 | D40: =SUM(D41:D42) -> 0 | E40: =SUM(E41:E42) -> 0 | F40: =SUM(F41:F42) -> 0 | G40: =SUM(G41:G42) -> 0 | H40: =SUM(H41:H42) -> 0 | I40: =SUM(I41:I42) -> 0 | J40: =SUM(J41:J42) -> 0 | ... P40: =SUM(P41:P42) -> 0
A41: Recursos para Cobertura de Insuficiências Financeiras | B41: 3.5.1.3.2.01.01.00.00.00
A42: Recurso para Cobertura de Déficit Financeiro | B42: 3.5.1.3.2.02.01.00.00.00
A44: RCL | B44: ( 1 - 2 - 3 - 4 - 5 - 6 - 7 - 8 - 9 + 10) | C44: =C45-C46-C47-C53-C56-C58-C61-C64-C67+C75 -> 1337176.9 | D44: =D45-D46-D47-D53-D56-D58-D61-D64-D67+D75 -> 1126788.8 | E44: =E45-E46-E47-E53-E56-E58-E61-E64-E67+E75 -> 1275546.3 | F44: =F45-F46-F47-F53-F56-F58-F61-F64-F67+F75 -> 1193296.5 | G44: =G45-G46-G47-G53-G56-G58-G61-G64-G67+G75 -> 1159745.8 | H44: =H45-H46-H47-H53-H56-H58-H61-H64-H67+H75 -> 1869614.2 | I44: =I45-I46-I47-I53-I56-I58-I61-I64-I67+I75 -> 1301843.1 | J44: =J45-J46-J47-J53-J56-J58-J61-J64-J67+J75 -> 1375536.5 | ... P44: =P45-P46-P47-P53-P56-P58-P61-P64-P67+P75 -> 1384536.9
A45: 1 - RECEITAS CORRENTES | B45: 1.0.0.0.00.00.00.00.00 | C45: 1645089.9 | D45: 1428374.8 | E45: 1563079.4 | F45: 1480372.3 | G45: 1435060.4 | H45: 2315791.5 | I45: 1758397.9 | J45: 1888341.4 | K45: 2020714.2 | L45: 2111521.5 | M45: 2210806.5 | N45: 1869631.4 | O45: 1854871.2 | P45: 1824460.2
A46: 2 - DEDUÇÕES DAS RECEITAS CORRENTES | B46: 9.1.0.0.0.00.00.00.00.00 | C46: 172091.37 | D46: 183665.23 | E46: 217481.65 | F46: 175974.04 | G46: 182751.84 | H46: 266224.47 | I46: 211095.57 | J46: 235567.69 | K46: 229666.97 | L46: 245674.2 | M46: 308383.63 | N46: 214113.46 | O46: 183168.89 | P46: 252119.76
A47: 3 - IRRF sobre Rendimentos do Trabalho | C47: =SUM(C48:C52) -> 18460.44 | D47: =SUM(D48:D52) -> 17140.48 | E47: =SUM(E48:E52) -> 18087.79 | F47: =SUM(F48:F52) -> 22138.8 | G47: =SUM(G48:G52) -> 18898.33 | H47: =SUM(H48:H52) -> 38476.56 | I47: =SUM(I48:I52) -> 33895.46 | J47: =SUM(J48:J52) -> 27809.79 | ... P47: =SUM(P48:P52) -> 23221.49
A48: Ativos / Inativos Poder Executivo / Indiretas | B48: 1.1.1.2.04.31.01.00.00 | C48: 17605.16 | D48: 16294.21 | E48: 17232.51 | F48: 21283.52 | G48: 18043.05 | H48: 36722 | I48: 32362.53 | J48: 26343.46 | K48: 22415.76 | L48: 22288.74 | M48: 21984.55 | N48: 30146.45 | O48: 24493.39 | P48: 21935.19
A49: Ativos / Inativos Poder Legislativo | B49: 1.1.1.2.04.31.02.00.00 | C49: 855.28 | D49: 846.27 | E49: 855.28 | F49: 855.28 | G49: 855.28 | H49: 1754.56 | I49: 1532.93 | J49: 1466.33 | K49: 1272.34 | L49: 1272.34 | M49: 1273.78 | N49: 1670.93 | O49: 1458.58 | P49: 1286.3
A50: Multas e Juros de Mora do IRRF | B50: 1.9.1.1.02.03.00.00.00
...

Sheet STN
A1: Índice de Despesa total com Pessoal (metodologia da STN - MDF 6ª edição)
A2: Item | C2: 42186 | D2: 42217 | E2: 42248 | F2: 42278 | G2: 42309 | H2: 42339 | I2: 42370 | J2: 42401 | K2: 42430 | L2: 42461 | M2: 42491 | N2: 42522 | O2: 42552 | P2: 42583
A3: DTP/RCL | N3: =IF(N19>0,N4/N5,"") -> 0.53913806 | O3: =IF(O19>0,O4/O5,"") -> 0.53922409 | P3: =IF(P19>0,P4/P5,"") -> 0.53289257
A4: Despesa Total com Pessoal (últimos 12 meses) | N4: =SUM(C7:N7) -> 9950689.2 | O4: =SUM(D7:O7) -> 10056460 | P4: =SUM(E7:P7) -> 10108770
A5: Receita Corrente Líquida (últimos 12 meses) | N5: =SUM(C19:N19) -> 18456663 | O5: =SUM(D19:O19) -> 18649871 | P5: =SUM(E19:P19) -> 18969622
A7: DTP | B7: (1 - 2) | C7: =C8-C9 -> 715215.81 | D7: =D8-D9 -> 723875.33 | E7: =E8-E9 -> 726315.81 | F7: =F8-F9 -> 756180.94 | G7: =G8-G9 -> 732006.3 | H7: =H8-H9 -> 1402374.5 | I7: =I8-I9 -> 846485.08 | J7: =J8-J9 -> 831864.81 | ... P7: =P8-P9 -> 776185.98
A8: 1 - PESSOAL E ENCARGOS SOCIAIS | B8: 3.1.0.0.00.00.00.00.00 | C8: =TCERS!C8 -> 784063.29 | D8: =TCERS!D8 -> 792722.81 | E8: =TCERS!E8 -> 795163.29 | F8: =TCERS!F8 -> 825028.42 | G8: =TCERS!G8 -> 800853.78 | H8: =TCERS!H8 -> 1541354.6 | I8: =TCERS!I8 -> 950180.06 | J8: =TCERS!J8 -> 944216.23 | ... P8: =TCERS!P8 -> 895845.18
A9: 2 - DEDUÇÕES | C9: =SUM(C10:C17) -> 68847.48 | D9: =SUM(D10:D17) -> 68847.48 | E9: =SUM(E10:E17) -> 68847.48 | F9: =SUM(F10:F17) -> 68847.48 | G9: =SUM(G10:G17) -> 68847.48 | H9: =SUM(H10:H17) -> 138980.08 | I9: =SUM(I10:I17) -> 103694.98 | J9: =SUM(J10:J17) -> 112351.42 | ... P9: =SUM(P10:P17) -> 119659.2
A10: Ajuda de Custo
A11: Auxílios
A12: Indenizações (exceto a Trabalhista)
A13: Sentenças judiciais de competências anteriores
A14: Inativos e Pensionistas na fonte 0050 RPPS | C14: =57711.23+11136.25 -> 68847.48 | D14: =57711.23+11136.25 -> 68847.48 | E14: =57711.23+11136.25 -> 68847.48 | F14: =57711.23+11136.25 -> 68847.48 | G14: =57711.23+11136.25 -> 68847.48 | H14: =116707.58+22272.5 -> 138980.08 | I14: =77284.95+26410.03 -> 103694.98 | J14: =81897.21+30454.21 -> 112351.42 | K14: =79860.1+30334.38 -> 110194.48 | L14: =79860.1+30334.38 -> 110194.48 | M14: =79860.1+30334.38 -> 110194.48 | N14: =79860.1+30744.31 -> 110604.41 | O14: =80625.97+37678.09 -> 118304.06 | P14: =78832.16+40827.04 -> 119659.2
A15: Despesas de Exercícios Anteriores (desde que de competências anteriores)
A16: Auxílio Medicamento
A17: Indenizações e Restituições Trabalhistas
A19: RCL | B19: ( 1 - 2 - 3 - 4 - 5) | C19: =C20-C21-C22-C25-C27 -> 1426338.3 | D19: =D20-D21-D22-D25-D27 -> 1199668.7 | E19: =E20-E21-E22-E25-E27 -> 1300222.4 | F19: =F20-F21-F22-F25-F27 -> 1259317 | G19: =G20-G21-G22-G25-G27 -> 1206545.4 | H19: =H20-H21-H22-H25-H27 -> 1912786.6 | I19: =I20-I21-I22-I25-I27 -> 1547302.4 | J19: =J20-J21-J22-J25-J27 -> 1593866.6 | ... P19: =P20-P21-P22-P25-P27 -> 1519419.1
A20: 1 - RECEITAS CORRENTES | B20: 1.0.0.0.00.00.00.00.00 | C20: =TCERS!C45 -> 1645089.9 | D20: =TCERS!D45 -> 1428374.8 | E20: =TCERS!E45 -> 1563079.4 | F20: =TCERS!F45 -> 1480372.3 | G20: =TCERS!G45 -> 1435060.4 | H20: =TCERS!H45 -> 2315791.5 | I20: =TCERS!I45 -> 1758397.9 | J20: =TCERS!J45 -> 1888341.4 | ... P20: =TCERS!P45 -> 1824460.2
A21: 2 - DEDUÇÕES DAS RECEITAS CORRENTES (exceto para o FUNDEB) | B21: 9.1.0.0.0.00.00.00.00.00 | C21: =TCERS!C46-C27 -> 6515.57 | D21: =TCERS!D46-D27 -> 1907.16 | E21: =TCERS!E46-E27 -> 21840.47 | F21: =TCERS!F46-F27 -> 540.67 | G21: =TCERS!G46-G27 -> 0 | H21: =TCERS!H46-H27 -> 177.17 | I21: =TCERS!I46-I27 -> 0 | J21: =TCERS!J46-J27 -> 2133.74 | ... P21: =TCERS!P46-P27 -> 26203.5
A22: 3 - Contribuições dos Servidores Ativos / Inativos / Pensionistas para o RPPS | C22: =SUM(C23:C24) -> 46660.27 | D22: =SUM(D23:D24) -> 45040.9 | E22: =SUM(E23:E24) -> 45375.29 | F22: =SUM(F23:F24) -> 45081.3 | G22: =SUM(G23:G24) -> 45763.08 | H22: =SUM(H23:H24) -> 136780.42 | I22: =SUM(I23:I24) -> 0 | J22: =SUM(J23:J24) -> 58907.16 | ... P22: =SUM(P23:P24) -> 52921.44
A23: Contribuição Social para o Financiamento da Seguridade Social | B23: 1.2.1.0.01.00.00.00.00 | C23: =TCERS!C54 -> 0 | D23: =TCERS!D54 -> 0 | E23: =TCERS!E54 -> 0 | F23: =TCERS!F54 -> 0 | G23: =TCERS!G54 -> 0 | H23: =TCERS!H54 -> 0 | I23: =TCERS!I54 -> 0 | J23: =TCERS!J54 -> 0 | ... P23: =TCERS!P54 -> 0
A24: Contribuição para o RPPS do Servidor Público | B24: 1.2.1.0.29.00.00.00.00 | C24: =TCERS!C55 -> 46660.27 | D24: =TCERS!D55 -> 45040.9 | E24: =TCERS!E55 -> 45375.29 | F24: =TCERS!F55 -> 45081.3 | G24: =TCERS!G55 -> 45763.08 | H24: =TCERS!H55 -> 136780.42 | I24: =TCERS!I55 -> 0 | J24: =TCERS!J55 -> 58907.16 | ... P24: =TCERS!P55 -> 52921.44
A25: 4 - Compensação Previdenciária do RPPS | C25: =SUM(C26) -> 0 | D25: =SUM(D26) -> 0 | E25: =SUM(E26) -> 0 | F25: =SUM(F26) -> 0 | G25: =SUM(G26) -> 0 | H25: =SUM(H26) -> 0 | I25: =SUM(I26) -> 0 | J25: =SUM(J26) -> 0 | ... P25: =SUM(P26) -> 0
A26: Compensações Financeiras Entre RGPS e RPPS | B26: 1.9.2.2.10.00.00.00.00 | C26: =TCERS!C57 -> 0 | D26: =TCERS!D57 -> 0 | E26: =TCERS!E57 -> 0 | F26: =TCERS!F57 -> 0 | G26: =TCERS!G57 -> 0 | H26: =TCERS!H57 -> 0 | I26: =TCERS!I57 -> 0 | J26: =TCERS!J57 -> 0 | ... P26: =TCERS!P57 -> 0
A27: 5 - Deduções para o Fundeb | C27: =82184.08+103.2+636.96+70865.73+10260.08+1525.75 -> 165575.8 | D27: =96120.03+31.1+636.96+80937.75+2820.96+1211.27 -> 181758.07 | E27: =80135.85+574.66+636.96+111432.19+804.39+2057.13 -> 195641.18 | F27: =91207.87+3152.01+636.96+77577.22+1018.97+1840.34 -> 175433.37 | G27: =102980.86+334.85+636.96+76865.93+197.01+1736.23 -> 182751.84 | H27: =118416.19+260.92+636.96+134744.07+10311.11+1678.05 -> 266047.3 | I27: 211095.57 | J27: 233433.95 | K27: 218784.62 | L27: 245674.2 | M27: 281790.04 | N27: 191710.22 | O27: 183168.89 | P27: 225916.26
