Workbook

Sheet BO-REC
A1: BALANÇO ORÇAMENTÁRIO
A2: EXERCÍCIO DE 2015 | B2: DE 01/01/2015 A 31/12/2015
A3: RECEITAS ORÇAMENTÁRIAS | B3: PREVISÃO INICIAL | C3: PREVISÃO ATUALIZADA (a) | D3: RECEITAS REALIZADAS (b) | E3: SALDO (c = b-a)
A4: RECETAS CORRENTES | B4: =B5+B9+B13+B21+B25+B30+B31+B38 -> 0 | C4: =C5+C9+C13+C21+C25+C30+C31+C38 -> 0 | D4: =D5+D9+D13+D21+D25+D30+D31+D38 -> 0 | E4: =D4-C4 -> 0
A5: RECEITA TRIBUTÁRIA | B5: =SUM(B6:B8) -> 0 | C5: =SUM(C6:C8) -> 0 | D5: =SUM(D6:D8) -> 0 | E5: =D5-C5 -> 0
A6: Impostos | E6: =D6-C6 -> 0
A7: Taxas | E7: =D7-C7 -> 0
A8: Contribuição de melhoria | E8: =D8-C8 -> 0
A9: RECEITA DE CONTRIBUIÇÕES | B9: =SUM(B10:B12) -> 0 | C9: =SUM(C10:C12) -> 0 | D9: =SUM(D10:D12) -> 0 | E9: =D9-C9 -> 0
A10: Contribuição social | E10: =D10-C10 -> 0
A11: Contribuição de intervenção no domínio econômico | E11: =D11-C11 -> 0
A12: Contribuição de iluminação pública | E12: =D12-C12 -> 0
A13: RECEITA PATRIMONIAL | B13: =SUM(B14:B20) -> 0 | C13: =SUM(C14:C20) -> 0 | D13: =SUM(D14:D20) -> 0 | E13: =D13-C13 -> 0
A14: Receitas imobiliárias | E14: =D14-C14 -> 0
A15: Receitas de valores mobiliários | E15: =D15-C15 -> 0
A16: Receitas de concessões e permissões | E16: =D16-C16 -> 0
A17: Compensações financeiras | E17: =D17-C17 -> 0
A18: Receita decorrente do direito de exploração de bens públicos em áreas de domínio público | E18: =D18-C18 -> 0
A19: Receita de cessão de direitos | E19: =D19-C19 -> 0
A20: Outras receitas patrimoniais | E20: =D20-C20 -> 0
A21: RECEITA AGROPECUÁRIA | B21: =SUM(B22:B24) -> 0 | C21: =SUM(C22:C24) -> 0 | D21: =SUM(D22:D24) -> 0 | E21: =D21-C21 -> 0
A22: Receita da produção vegetal | E22: =D22-C22 -> 0
A23: Receita da produção animal e derivados | E23: =D23-C23 -> 0
A24: Outras receitas agropecuárias | E24: =D24-C24 -> 0
A25: RECEITA INDUSTRIAL | B25: =SUM(B26:B29) -> 0 | C25: =SUM(C26:C29) -> 0 | D25: =SUM(D26:D29) -> 0 | E25: =D25-C25 -> 0
A26: Receita da indústria extrativa mineral | E26: =D26-C26 -> 0
A27: Receita da indústria de transformação | E27: =D27-C27 -> 0
A28: Receita da indústria de construção | E28: =D28-C28 -> 0
A29: Outras receitas industriais | E29: =D29-C29 -> 0
A30: RECEITA DE SERVIÇOS | E30: =D30-C30 -> 0
A31: TRANSFERÊNCIAS CORRENTES | B31: =SUM(B32:B37) -> 0 | C31: =SUM(C32:C37) -> 0 | D31: =SUM(D32:D37) -> 0 | E31: =D31-C31 -> 0
A32: Transferências intergovernamentais | E32: =D32-C32 -> 0
A33: Transferências de instituições privadas | E33: =D33-C33 -> 0
A34: Transferências do exterior | E34: =D34-C34 -> 0
A35: Transferências de pessoas | E35: =D35-C35 -> 0
A36: Transferências de convênios | E36: =D36-C36 -> 0
A37: Transferências para o combate à fome | E37: =D37-C37 -> 0
A38: OUTRAS RECEITAS CORRENTES | B38: =SUM(B39:B43) -> 0 | C38: =SUM(C39:C43) -> 0 | D38: =SUM(D39:D43) -> 0 | E38: =D38-C38 -> 0
A39: Multas e juros de mora | E39: =D39-C39 -> 0
A40: Indenizações e restituições | E40: =D40-C40 -> 0
...

Sheet BO-DESP
A1: BALANÇO ORÇAMENTÁRIO
A2: ='BO-REC'!A2 -> EXERCÍCIO DE 2015 | E2: ='BO-REC'!B2 -> DE 01/01/2015 A 31/12/2015
A3: DESPESAS ORÇAMENTÁRIAS | B3: DOTAÇÃO INICIAL (d) | C3: DOTAÇÃO ATUALIZADA (e) | D3: DESPESAS EMPENHADAS (f) | E3: DESPESAS LIQUIDADAS (g) | F3: DESPESAS PAGAS (h) | G3: SALDO DA DOTAÇÃO (i)=(e)-(f)
A4: DESPESAS CORRENTES | B4: =SUM(B5:B7) -> 0 | C4: =SUM(C5:C7) -> 0 | D4: =SUM(D5:D7) -> 0 | E4: =SUM(E5:E7) -> 0 | F4: =SUM(F5:F7) -> 0 | G4: =C4-D4 -> 0
A5: PESSOAL E ENCARGOS SOCIAIS | G5: =C5-D5 -> 0
A6: JUROS E ENCARGOS DA DÍVIDA | G6: =C6-D6 -> 0
A7: OUTRAS DESPESAS CORRENTES | G7: =C7-D7 -> 0
A8: DESPESAS DE CAPITAL | B8: =SUM(B9:B11) -> 0 | C8: =SUM(C9:C11) -> 0 | D8: =SUM(D9:D11) -> 0 | E8: =SUM(E9:E11) -> 0 | F8: =SUM(F9:F11) -> 0 | G8: =C8-D8 -> 0
A9: INVESTIMENTOS | G9: =C9-D9 -> 0
A10: INVERSÕES FINANCEIRAS | G10: =C10-D10 -> 0
A11: AMORTIZAÇÃO DA DÍVIDA | G11: =C11-D11 -> 0
A12: RESERVA DE CONTINGÊNCIA | G12: =C12-D12 -> 0
A13: RESERVA DO RPPS | G13: =C13-D13 -> 0
A14: SUBTOTAL DAS DESPESAS (VI) | B14: =B4+B8+B12+B13 -> 0 | C14: =C4+C8+C12+C13 -> 0 | D14: =D4+D8+D12+D13 -> 0 | E14: =E4+E8+E12+E13 -> 0 | F14: =F4+F8+F12+F13 -> 0 | G14: =C14-D14 -> 0
A15: AMORTIZAÇÃO DA DÍVIDA/REFINANCIAMENTO (VII) | B15: =B16+B19 -> 0 | C15: =C16+C19 -> 0 | D15: =D16+D19 -> 0 | E15: =E16+E19 -> 0 | F15: =F16+F19 -> 0 | G15: =C15-D15 -> 0
A16: Amortização da dívida interna | B16: =SUM(B17:B18) -> 0 | C16: =SUM(C17:C18) -> 0 | D16: =SUM(D17:D18) -> 0 | E16: =SUM(E17:E18) -> 0 | F16: =SUM(F17:F18) -> 0 | G16: =C16-D16 -> 0
A17: Dívida mobiliária | G17: =C17-D17 -> 0
A18: Outras dívidas | G18: =C18-D18 -> 0
A19: Amortização da dívida externa | B19: =SUM(B20:B21) -> 0 | C19: =SUM(C20:C21) -> 0 | D19: =SUM(D20:D21) -> 0 | E19: =SUM(E20:E21) -> 0 | F19: =SUM(F20:F21) -> 0 | G19: =C19-D19 -> 0
A20: Dívida mobiliária | G20: =C20-D20 -> 0
A21: Outras dívidas | G21: =C21-D21 -> 0
A22: SUBTOTAL COM REFINANCIAMENTO (VIII=VI+VII) | B22: =B14+B15 -> 0 | C22: =C14+C15 -> 0 | D22: =D14+D15 -> 0 | E22: =E14+E15 -> 0 | F22: =F14+F15 -> 0 | G22: =C22-D22 -> 0
A23: SUPERÁVIT (IX) | D23: =IF(D22<'BO-REC'!D73,'BO-REC'!D73-'BO-DESP'!D22,0) -> 0
A24: TOTAL (X=VIII+IX) | B24: =B22+B23 -> 0 | C24: =C22+C23 -> 0 | D24: =D22+D23 -> 0 | E24: =E22+E23 -> 0 | F24: =F22+F23 -> 0 | G24: =G22+G23 -> 0
A26: ANEXO I - DEMONTRATIVO DE EXECUÇÃO DOS RESTOS A PAGAR NÃO PROCESSADOS
A27: RESTOS A PAGAR NÃO PROCESSADOS | B27: INSCRITOS | D27: LIQUIDADOS (c) | E27: PAGOS (d) | F27: CANCELADOS (e) | G27: SALDO (f=a+b-d-e)
B28: EM EXERCÍCIOS ANTERIORES (a) | C28: EM 31 DE DEZ. DO EXERC. ANTERIOR (b)
A29: DESPESAS CORRENTES | B29: =SUM(B30:B32) -> 0 | C29: =SUM(C30:C32) -> 0 | D29: =SUM(D30:D32) -> 0 | E29: =SUM(E30:E32) -> 0 | F29: =SUM(F30:F32) -> 0 | G29: =B29+C29-E29-F29 -> 0
A30: PESSOAL E ENCARGOS SOCIAIS | G30: =B30+C30-E30-F30 -> 0
A31: JUROS E ENCARGOS DA DÍVIDA | G31: =B31+C31-E31-F31 -> 0
A32: OUTRAS DESPESAS CORRENTES | G32: =B32+C32-E32-F32 -> 0
A33: DESPESAS DE CAPITAL | B33: =SUM(B34:B36) -> 0 | C33: =SUM(C34:C36) -> 0 | D33: =SUM(D34:D36) -> 0 | E33: =SUM(E34:E36) -> 0 | F33: =SUM(F34:F36) -> 0 | G33: =B33+C33-E33-F33 -> 0
A34: INVESTIMENTOS | G34: =B34+C34-E34-F34 -> 0
A35: INVERSÕES FINANCEIRAS | G35: =B35+C35-E35-F35 -> 0
A36: AMORTIZAÇÃO DA DÍVIDA | G36: =B36+C36-E36-F36 -> 0
A37: TOTAL | B37: =B29+B33 -> 0 | C37: =C29+C33 -> 0 | D37: =D29+D33 -> 0 | E37: =E29+E33 -> 0 | F37: =F29+F33 -> 0 | G37: =B37+C37-E37-F37 -> 0
A39: ANEXO II - DEMONTRATIVO DE EXECUÇÃO DOS RESTOS A PAGAR PROCESSADOS E NÃO PROCESSADOS LIQUIDADOS
A40: RESTOS A PAGAR PROCESSADOS E NÃO PROCESSADOS LIQUIDADOS | B40: INSCRITOS | D40: PAGOS (c) | E40: CANCELADOS (d) | F40: SALDO (f=a+b-c-d)
B41: EM EXERCÍCIOS ANTERIORES (a) | C41: EM 31 DE DEZ. DO EXERC. ANTERIOR (b)
A42: DESPESAS CORRENTES | B42: =SUM(B43:B45) -> 0 | C42: =SUM(C43:C45) -> 0 | D42: =SUM(D43:D45) -> 0 | E42: =SUM(E43:E45) -> 0 | F42: =B42+C42-D42-E42 -> 0
...

Sheet BF
A1: BALANÇO FINANCEIRO
A2: ='BO-REC'!A2 -> EXERCÍCIO DE 2015 | D2: ='BO-REC'!B2 -> DE 01/01/2015 A 31/12/2015
A3: INGRESSOS | D3: DISPÊNDIOS
A4: ESPECIFICAÇÃO | B4: Exercício Atual | C4: Exercício Anterior | D4: ESPECIFICAÇÃO | E4: Exercício Atual | F4: Exercício Anterior
A5: Receita Orçamentária (I) | B5: =B6+B7+B13 -> 0 | C5: =C6+C7+C13 -> 0 | D5: Despesa Orçamentaria (VI) | E5: =E6+E7 -> 0 | F5: =F6+F7 -> 0
A6: Ordinária | D6: Ordinária
A7: Vinculada | B7: =SUM(B8:B12) -> 0 | C7: =SUM(C8:C12) -> 0 | D7: Vinculada | E7: =SUM(E8:E12) -> 0 | F7: =SUM(F8:F12) -> 0
A8: Previdência Social | D8: Previdência Social
A9: Destinadas à Saúde | D9: Destinadas à Saúde
A10: Destinadas à Educação | D10: Destinadas à Educação
A11: Destinadas à Assistência Social | D11: Destinadas à Assistência Social
A12: Outras receitas vinculadas | D12: Outras despesas vinculadas
D13: Pagamento de restos a pagar (VII)
A14: Transferências financeiras recebidas (II) | D14: Transferências financeiras concedidas (VIII)
A15: Recebimentos extraorçamentários (III) | D15: Pagamentos extraorçamentários (IX)
A16: Saldo em espécie do exercício anterior (IV) | D16: Saldo em espécie para o exercício seguinte (X)
A17: TOTAL (VI=I+II+III+IV+V) | B17: =B5+B14+B15+B16 -> 0 | C17: =C5+C14+C15+C16 -> 0 | D17: TOTAL (XII=VI+VII+VIII+IX+X+XI) | E17: =E5+E14+E15+E16+E13 -> 0 | F17: =F5+F14+F15+F16+F13 -> 0
A19: QUADRO I - RECEBIMENTOS E PAGAMENTOS EXTRAORÇAMENTÁRIOS
A20: RECEBIMENTOS | C20: VALOR | D20: PAGAMENTOS | F20: VALOR
A31: TOTAL | C31: =SUM(C21:C30) -> 0 | D31: TOTAL | F31: =SUM(F21:F30) -> 0
A33: QUADRO II - TRANSFERÊNCIAS FINANCEIRAS INTRA OFSS (EXCLUÍDAS DO BALANÇO FINANCEIRO CONSOLIDADO)
A34: TRANSFERÊNCIAS FINANCEIRAS RECEBIDAS | C34: VALOR | D34: TRANSFERÊNCIAS FINANCEIRAS CONCEDIDAS | E34: VALOR
A36: TOTAL | C36: =SUM(C35:C35) -> 0 | D36: =SUM(D35:D35) -> 0 | E36: =SUM(E35:E35) -> 0
A38: QUADRO III - DEDUÇÕES DAS RECEITAS ORÇAMENTÁRIAS
A39: NATUREZA DA DEDUÇÃO | E39: VALOR
A43: TOTAL | E43: =SUM(E40:E42) -> 0
A45: QUADRO IV - AJUSTES E PERDAS EM INVESTIMENTOS DO RPPS
A46: INVESTIMENTO | B46: SALDO 31/12/X-1 | C46: PROVISÃO | D46: REVERSÃO DA PROVISÃO | E46: SALDO 31/12/X | F46: PERDAS
A53: TOTAL | B53: =SUM(B47:B52) -> 0 | C53: =SUM(C47:C52) -> 0 | D53: =SUM(D47:D52) -> 0 | E53: =SUM(E47:E52) -> 0 | F53: =SUM(F47:F52) -> 0
A55: QUOCIENTES - BALANÇO FINANCEIRO
A56: QUOCIENTE | F56: VALOR
A57: ORÇAMENTÁRIO DO RESULTADO FINANCEIRO: resultante da relação entre o resultado orçamentário (receita orçamentária - despesa orçamentária) e a variação do saldo em espécie e indica a parcela da variação do saldo do disponível que pode ser explicada pelo resultado orçamentário. | F57: =('BO-REC'!D65-'BO-DESP'!D22)/(BF!E16-BF!B16) -> #DIV/0!
A58: RESULTADO DOS SALDOS FINANCEIROS: resultante da relação entre o saldo que passa para o exercício seguinte e o aldo do exercício anterior, indicando o impacto do resultado financeiro sobre o saldo em espécie. | F58: =E16/B16 -> #DIV/0!

Sheet DVP
A1: DEMONSTRAÇÃO DAS VARIAÇÕES PATRIMONIAIS
A2: ='BO-REC'!A2 -> EXERCÍCIO DE 2015 | B2: ='BO-REC'!B2:E2 -> DE 01/01/2015 A 31/12/2015
A3: VARIAÇÕES PATRIMONIAIS QUANTITATIVAS | B3: Exercício Atual | C3: Exercício Anterior
A4: VARIAÇÕES PATRIMONIAIS AUMENTATIVAS | B4: =B5+B9+B14+B18+B25+B34+B38 -> 0 | C4: =C5+C9+C14+C18+C25+C34+C38 -> 0
A5: Impostos, taxas e contribuições de melhoria | B5: =SUM(B6:B8) -> 0 | C5: =SUM(C6:C8) -> 0
A6: Impostos
A7: Taxas
A8: Contribuições de melhoria
A9: Contribuições | B9: =SUM(B10:B13) -> 0 | C9: =SUM(C10:C13) -> 0
A10: Contribuições sociais
A11: Contribuições de intervenção no domínio econômico
A12: Contribuição de iluminação pública
A13: Contribuição de interesse de categorias profissionais
A14: Exploração e venda de bens, serviços e direitos | B14: =SUM(B15:B17) -> 0 | C14: =SUM(C15:C17) -> 0
A15: Venda de mercadorias
A16: Venda de produtos
A17: Exploração de bens, direitos e prestação de serviços
A18: Variações patrimoniais aumentativas financeiras | B18: =SUM(B19:B24) -> 0 | C18: =SUM(C19:C24) -> 0
A19: Juros e encargos de empréstimos e financiamentos concedidos
A20: Juros e encargos de mora
A21: Variações monetárias e cambiais
A22: Descontos financeiros obtidos
A23: Remuneração de depósitos bancários e aplicações financeiras
A24: Outras variações aumentativas - financeiras
A25: Transferências e delegações recebidas | B25: =SUM(B26:B33) -> 0 | C25: =SUM(C26:C33) -> 0
A26: Transferências intragovernamentais
A27: Transferências intergovernamentais
A28: Transferências das instituições privadas
A29: Transferências das instituições multigovernamentais
A30: Transferências de consórcios públicos
A31: Transferências do exterior
A32: Delegações recebidas
A33: Transferências de pessoas físicas
A34: Valorização e ganhos com ativos | B34: =SUM(B35:B37) -> 0 | C34: =SUM(C35:C37) -> 0
A35: Reavaliação de ativos
A36: Ganhos com alienação
A37: Ganhos com incorporação de ativos por descobertas e nascimentos
A38: Outras variações patrimoniais aumentativas | B38: =SUM(B39:B42) -> 0 | C38: =SUM(C39:C42) -> 0
A39: Variação patrimonial aumentativa a classificar
A40: Resultado positivo de participações
...

Sheet BP
A1: BALANÇO PATRIMONIAL
A2: ='BO-REC'!A2 -> EXERCÍCIO DE 2015 | D2: ='BO-REC'!B2 -> DE 01/01/2015 A 31/12/2015
A3: ATIVO | D3: PASSIVO
A4: ESPECIFICAÇÃO | B4: Exercício Atual | C4: Exercício Anterior | D4: ESPECIFICAÇÃO | E4: Exercício Atual | F4: Exercício Anterior
A5: ATIVO CIRCULANTE | B5: =SUM(B6:B7,B15:B18) -> 0 | C5: =SUM(C6:C7,C15:C18) -> 0 | D5: PASSIVO CIRCULANTE | E5: =SUM(E6:E12) -> 0 | F5: =SUM(F6:F12) -> 0
A6: Caixa e equivalentes de caixa | D6: Obrigações trabalhistas, previdenciárias e assistencias a pagar a curto prazo
A7: Créditos a curto prazo | B7: =SUM(B8:B14) -> 0 | C7: =SUM(C8:C14) -> 0 | D7: Emprestimos e financiamentos a curto prazo
A8: Clientes | D8: Fornecedores e contas a pagar a curto prazo
A9: Créditos tributários a receber | D9: Obrigações fiscais a curto prazo
A10: Dívida ativa tributária | D10: Obrigações de repartição a outros entes
A11: Dívida ativa não tributária - clientes | D11: Provisões a curto prazo
A12: Créditos de transferências a receber | D12: Demais obrigações a curto prazo
A13: Empréstimos e financiamentos concedidos
A14: (-) Ajuste de perdas de créditos a curto prazo
A15: Demais créditos e valores a curto prazo
A16: Investimentos e aplicações temporárias a curto prazo
A17: Estoques
A18: VPD pagas antecipadamente
A19: ATIVO NÃO-CIRCULANTE | B19: =B20+B32+B38 -> 0 | C19: =C20+C32+C38 -> 0 | D19: PASSIVO NÃO CIRCULANTE | E19: =SUM(E20:E27) -> 0 | F19: =SUM(F20:F27) -> 0
A20: Ativo realizável a longo prazo | B20: =SUM(B21,B28:B31) -> 0 | C20: =SUM(C21,C28:C31) -> 0 | D20: Obrigações trabalhistas, previdenciárias e assistencias a pagar a longo prazo
A21: Créditos a longo prazo | B21: =SUM(B22:B27) -> 0 | C21: =SUM(C22:C27) -> 0 | D21: Emprestimos e financiamentos a longo prazo
A22: Clientes | D22: Fornecedores a longo prazo
A23: Créditos tributários a receber | D23: Obrigações fiscais a longo prazo
A24: Dívida ativa tributária | D24: Obrigações de repartição a outros entes
A25: Dívida ativa não tributária - clientes | D25: Provisões a longo prazo
A26: Empréstimos e financiamentos concedidos | D26: Demais obrigações a longo prazo
A27: (-) Ajuste de perdas de créditos a curto prazo | D27: Resultado diferido
A28: Demais créditos e valores a longo prazo | D28: TOTAL DO PASSIVO | E28: =E5+E19 -> 0 | F28: =F5+F19 -> 0
A29: Investimentos e aplicações temporárias a longo prazo | D29: PATRIMÔNIO LÍQUIDO
A30: Estoques | D30: ESPECIFICAÇÃO | E30: Exercício Atual | F30: Exercício Anterior
A31: VPD pagas antecipadamente | D31: Patrimônio social e capital social
A32: Investimentos | B32: =SUM(B33,B36:B37) -> 0 | C32: =SUM(C33,C36:C37) -> 0 | D32: Adiantamento para futuro aumento de capital
A33: Participações permanentes | B33: =SUM(B34:B35) -> 0 | C33: =SUM(C34:C35) -> 0 | D33: Reservas de capital
A34: Participações avaliadas pelo método de equivalência patrimonial | D34: Ajustes de avaliação patrimonial
A35: Participações avaliadas pelo método de custo | D35: Reservas de lucros
A36: Propriedades para investimento | D36: Demais reservas
A37: Demais investimentos permanentes | D37: Resultados acumulados | E37: =SUM(E38:E40) -> 0 | F37: =SUM(F38:F40) -> 0
A38: Imobilizado | B38: =SUM(B39:B41) -> 0 | C38: =SUM(C39:C41) -> 0 | D38: Resultado do exercício
A39: Bens móveis | D39: Resultados de exercícios anteriores
A40: Bens imóveis | D40: Ajustes de exercícios anteriores
...

Sheet DFC
A1: DEMONSTRAÇÃO DOS FLUXOS DE CAIXA
A2: ='BO-REC'!A2 -> EXERCÍCIO DE 2015 | B2: ='BO-REC'!B2:E2 -> DE 01/01/2015 A 31/12/2015
A3: ESPECIFICAÇÃO | B3: Exercício Atual | C3: Exercício Anterior
A4: FLUXOS E CAIXA DAS ATIVIDADES DAS OPERAÇÕES
A5: INGRESSOS | B5: =B6+B10+B17+B24 -> 1668185.6 | C5: =C6+C10+C17 -> 0
A6: RECEITAS DERIVADAS | B6: =SUM(B7:B9) -> 0 | C6: =SUM(C7:C9) -> 0
A7: Receita tributária
A8: Receita de contribuições
A9: Outras receitas derivadas
A10: RECEITAS ORIGINÁRIAS | B10: =SUM(B11:B16) -> 0 | C10: =SUM(C11:C16) -> 0
A11: Receita patrimonial
A12: Receita agropecuária
A13: Receita industrial
A14: Receita de serviços
A15: Outras receitas originárias
A16: Remuneração das disponibilidades
A17: TRANSFERÊNCIAS | B17: =B18+B23+B22 -> 0 | C17: =C18+C23+C22 -> 0
A18: Intergovernamentais | B18: =SUM(B19:B21) -> 0 | C18: =SUM(C19:C21) -> 0
A19: da União
A20: de Estados e Distrito Federal
A21: de Municípios
A22: Multigovernamentais
A23: Intragovernamentais
A24: RECEBIMENTOS EXTRA-ORÇAMENTÁRIOS | B24: =1668198.07-12.48 -> 1668185.6
A25: DESEMBOLSOS | B25: =B26+B47+B51+B57 -> 0 | C25: =C26+C47+C51+C57 -> 0
A26: PESSOAL E OUTRAS DESPESAS CORRENTES POR FUNÇÃO | B26: =SUM(B27:B46) -> 0 | C26: =SUM(C27:C46) -> 0
A27: Legislativa
A28: Judiciária
A29: Administração
A30: Cultura
A31: Defesa nacional
A32: Desporto e lazer
A33: Encargos especiais
A34: Gestão ambiental
A35: Segurança pública
A36: Comércio e serviços
A37: Habitação
A38: Agricultura
... A46: Urbanismo
A47: JUROS E ENCARGOS DA DÍVIDA | B47: =SUM(B48:B50) -> 0 | C47: =SUM(C48:C50) -> 0
...

Sheet Validação
A1: ITENS PARA VALIDAÇÃO DAS DCASP
A2: Valor 1 e Valor 2 sempre devem ser iguais
A3: ITEM 1 | B3: VALOR 1 | C3: ITEM 2 | D3: VALOR 2 | E3: DIFERENÇA
A4: Total de créditos especiais excluídas as reduções do BO | B4: ='BO-DESP'!B82-'BO-DESP'!E82 -> 0 | C4: Diferença entre dotação inicial e atualizada do BO | D4: ='BO-DESP'!C24-'BO-DESP'!B24 -> 0 | E4: =B4-D4 -> 0
A5: Total de superávit financeiro usado como origem de recursos para créditos adicionais do BO | B5: ='BO-DESP'!C82 -> 0 | C5: Superávit de saldos de exercícios anteriores do BO | D5: ='BO-REC'!D77 -> 0 | E5: =B5-D5 -> 0
A6: Total de reabertura usado como origem de recursos para créditos adicionais do BO | B6: ='BO-DESP'!G82 -> 0 | C6: Reabertura de saldos de exercícios anteriores do BO | D6: ='BO-REC'!D78 -> 0 | E6: =B6-D6 -> 0
A7: Receita orçamentária arrecadada do BO | B7: ='BO-REC'!D73 -> 0 | C7: Receita orçamentária do BF | D7: =BF!B5 -> 0 | E7: =B7-D7 -> 0
A8: Despesa orçamentária paga do BO | B8: ='BO-DESP'!F24 -> 0 | C8: Despesa orçamentária do BF | D8: =BF!E5 -> 0 | E8: =B8-D8 -> 0
A9: Saldo anterior do BF | B9: =BF!B16 -> 0 | C9: Saldo inicial da DFC | D9: =DFC!B78 -> 0 | E9: =B9-D9 -> 0
A10: Saldo final do BF | B10: =BF!E16 -> 0 | C10: Saldo final da DFC | D10: =DFC!B79 -> 0 | E10: =B10-D10 -> 0
A11: Saldo final do BF | B11: =BF!E16 -> 0 | C11: Caixa e equivalentes do BP + Investimentos BP | D11: =BP!B6+BP!B16 -> 0 | E11: =B11-D11 -> 0
A12: Recebimentos extraorçamentários do anexo do BF | B12: =BF!C31 -> 0 | C12: Recebimentos extraorçamentários do BF | D12: =BF!B15 -> 0 | E12: =B12-D12 -> 0
A13: Pagamentos extraorçamentários do anexo do BF | B13: =BF!F31 -> 0 | C13: Pagamentos extraorçamentários do BF | D13: =BF!E15 -> 0 | E13: =B13-D13 -> 0
A14: Resultado patrimonial da DVP | B14: =DVP!B93 -> 0 | C14: Resultado do exercício do BP | D14: =BP!E38 -> 0 | E14: =B14-D14 -> 0
A15: Caixa e equivalentes do BP + Investimentos BP | B15: =BP!B6+BP!B16 -> 0 | C15: Saldo final da DFC | D15: =DFC!B79 -> 0 | E15: =B15-D15 -> 0
A16: Superávit/déficit do anexo do BP | B16: =BP!F97 -> 0 | C16: Ativo Financeiro - Passivo financeiro | D16: =BP!B47-BP!E47 -> 0 | E16: =B16-D16 -> 0
